Workbook

Sheet How to use
A1: Gliped outreach tracker
A3: Tabs
A4: Leads | B4: Every lead with trigger, LinkedIn activity pattern, score and ready-to-send messages. One row per person. Add new batches at the bottom with the next ID (G061, G062, ...).
A5: Tracker | B5: Your working sheet. One row per lead ID. Fill the yellow cells as you go. Names, company, region and tier pull from Leads automatically by ID.
A6: Dashboard | B6: Counts and conversion rates by stage, region and activity pattern. Updates itself from Tracker.
A7: Sequence | B7: The shared outreach cadence, follow-up messages and send times.
A8: Lists | B8: Values behind the drop-downs. Edit here to change the options.
A10: How to fill the Tracker
A11: Status | B11: Pick from the drop-down. Move it forward each time something happens.
A12: Date columns | B12: Type dates as YYYY-MM-DD (for example 2026-09-29). Follow-up due dates calculate themselves.
A13: FU1 due | B13: First DM sent + 4 days. Turns red when overdue and FU1 sent is empty.
A14: FU2 due | B14: FU1 sent + 6 days. Turns red when overdue and FU2 sent is empty.
A15: Email | B15: Paste the verified work email in Leads (Email address). Tracker shows it and counts Email sent + 5 days for the email follow-up. Send LinkedIn first; email is the second channel for leads who don't accept or reply.
A16: Days since last touch | B16: Days since the latest date you've entered in that row.
A17: Yellow cells | B17: The only cells you need to edit. Grey or white cells are formulas or reference data.
A19: Example row (format only) | B19: G999 | Status: DM sent | Warm-up started 2026-09-26 | Connection sent 2026-10-01 | Accepted 2026-10-02 | First DM sent 2026-10-02 | FU1 due fills in as 2026-10-06 | Next action: send FU1 teardown offer
A21: Scoring | B21: Trigger in last 90 days (max 30) + profile gap (max 20) + fit (10) + active in last 30 days (10). Intent signals were not visible, so add +30 by hand when someone views your profile or engages with Gliped. Tier: 60+ Priority, 40 to 59 Warm, under 40 Nurture.
A22: Profile confirmed = No | B22: The LinkedIn link is a people search. Open it, match company and role, then paste the real profile URL into Leads and set Profile confirmed to Yes.
A23: Activity data | B23: Posting timelines come from publicly indexed LinkedIn posts, dated from each post's activity ID. The index only catches some posts, so 'last indexed own post' means at least that recent.

Sheet Leads
A1: ID | B1: Batch | C1: Date added | D1: Name | E1: Role | F1: Company | G1: Region | H1: City | I1: LinkedIn URL | J1: Profile confirmed | K1: Trigger | L1: Trigger date | M1: Source | N1: Activity pattern | O1: Last indexed own post | P1: Activity notes | Q1: Score | R1: Tier | S1: Angle | T1: Connection note | U1: First DM | V1: Teardown focus | W1: Notes | X1: Email address | Y1: Email subject | Z1: Email body | AA1: Email status | AB1: Email lookup note
A2: G001 | B2: 01 | C2: 2026-09-22 | D2: Ravi Ramachandran | E2: Founder & CEO | F2: Nua | G2: India | I2: https://www.linkedin.com/in/ravishankarramachandran | J2: Yes | K2: $50M Series C led by Peak XV and Filter Capital, around 7 Sep 2026. | L2: 2026-09 | N2: Milestone-only | O2: 2026-02 | P2: milestone-only. Indexed posts: the Nua x Zepto "zero irritation promise" campaign (Apr 2025) and a "Zero to Scale" video episode on building Nua (Feb 2026). The Series C shows up through FemTech Insider's post, but no post of his own is indexed yet. | Q2: 60 | R2: =IF(Q2>=60,"Priority",IF(Q2>=40,"Warm","Nurture")) | S2: the post-Series C window. Hiring, category leadership, and keeping the founder story alive between campaigns. | T2: Hi Ravi, congrats on the Series C. Came across your Zero to Scale episode on building Nua. [one line on a specific moment from it] Would be good to connect. | U2: Thanks for connecting, Ravi. Quick one. After a round like this, is your own LinkedIn something you want to put real time into? Or is Nua's page doing that job for now? | V2: headline vs the Series C story, no featured section pointing to Nua, and the gap between the video episode and what he writes himself. | W2: India. Warm, respectful tone. Expect a CoS or comms lead in the decision. | X2: ravi@nuawoman.com | Y2: Nua after the Series C | Z2: Hi Ravi, Congrats on the $50M Series C. Nua's story gets told at big moments, like the Zero to Scale episode, then it goes quiet. In women's wellness, the founder's voice is a trust asset between campaigns too. We run LinkedIn for founders: strategy, writing and posting, built around your voice. Worth a 15-minute call next week to see what that could look like for you? Prabal Gliped | LinkedIn personal branding for founders Not relevant? Reply "no" and I won't follow up. | AA2: Verified | AB2: Prospeo SMTP
A3: G002 | B3: 01 | C3: 2026-09-22 | D3: Karishma Rathaur | E3: Co-founder | F3: Firi | G3: India | I3: https://www.linkedin.com/in/karishmarathaur | J3: Yes | K3: Firi was incorporated in June 2026 and raised a $3M seed led by 360 ONE Asset, with Better Capital and Kunal Shah, in September. It runs 9-minute beauty delivery in Gurugram. Before this she co-built Honestly; she and co-founder Vivek Madani met at Uber India and Flipkart. | L3: 2026-06 | N3: Milestone-only | O3: 2024-04 | P3: almost invisible. One indexed personal post, about advice she got growing up (Apr 2024). | Q3: 60 | R3: =IF(Q3>=60,"Priority",IF(Q3>=40,"Warm","Nurture")) | S3: a launch-stage founder brand. Customers, first hires, and the next round all check the founder. | T3: Hi Karishma, saw the Firi news. Nine-minute beauty delivery is a bold promise. Following what you and Vivek are building. Would be good to connect. | U3: Thanks for connecting, Karishma. Curious how you're thinking about your own voice for Firi. In beauty, people buy from people. Is founder content part of the launch plan? | V3: headline still reflecting the old role, no Firi story on the profile, and what three posts a month could look like (building dark stores, what the AI picks up from Reddit and YouTube reviews, operator lessons from Uber and Flipkart). | W3: India, early stage and price-conscious. Lead with a starter plan and mention the pilot option early. | Y3: Firi's founder story | Z3: Hi Karishma, Nine-minute beauty delivery and a seed round in the same quarter. Strong start. In beauty, people buy from people. Right now Firi's story lives in press coverage, not on your LinkedIn, and that's where hires, partners and your next investors will look. We build founder brands on LinkedIn, from positioning to weekly posts. Open to a quick call to map out your first 90 days? Prabal Gliped | LinkedIn personal branding for founders Not relevant? Reply "no" and I won't follow up. | AA3: Not found
A4: G003 | B4: 01 | C4: 2026-09-22 | D4: Sadra Hosseini | E4: Co-founder & CEO | F4: Ryft | G4: UK | I4: https://www.linkedin.com/in/sadra-hosseini | J4: Yes | K4: €23M to speed up European expansion, Sep 2026. | L4: 2026-09 | N4: Went quiet | O4: 2025-04 | P4: went quiet. From 2022 to 2025 he posted steadily: FCA licence (56 comments), a practical post for founders who are fundraising, marketplace payments posts, Innovate UK grant. The last indexed post is Apr 2025. | Q4: 60 | R4: =IF(Q4>=60,"Priority",IF(Q4>=40,"Warm","Nurture")) | S4: entering new markets. Buyers in France, Germany and the Netherlands will look him up before taking a call. | T4: Hi Sadra, congrats on the raise and the push into Europe. Came across your post with advice for founders who are fundraising. [one line on the point you agreed with] Would be good to connect. | U4: Thanks for connecting, Sadra. One question. With Europe in focus, do you see your own LinkedIn doing any of the market-entry work? Or is that all sales and partnerships? | V4: a UK-only framing, the last post being 17 months ago, and a content line on marketplace payments for EU platforms. | W4: UK. Plain and understated. "Might be useful" over "huge opportunity". | X4: sadra@ryftpay.com | Y4: Ryft's European push | Z4: Hi Sadra, Congrats on the EUR 23M and the move into Europe. Buyers in new markets will look you up before they take a call. Your last post was in April 2025, and your FCA licence post shows your audience responds when you do post. We help founders turn that into a steady weekly presence without eating their week. Worth 15 minutes to talk through a Europe-facing plan? Prabal Gliped | LinkedIn personal branding for founders Not relevant? Reply "no" and I won't follow up. | AA4: Verified | AB4: Prospeo SMTP
A5: G004 | B5: 01 | C5: 2026-09-22 | D5: Erin Kelly | E5: Co-founder & CEO | F5: askpolly | G5: Canada | I5: https://www.linkedin.com/in/erinottawa | J5: Yes | K5: $3M seed led by Differential Ventures (with The 98 and Forum Ventures), Sep 2026, to grow go-to-market in the US. askpolly grew out of Advanced Symbolics and turns social media conversations into market research. | L5: 2026-09 | N5: Went quiet | O5: 2024-06 | P5: went quiet. Sporadic posts (a hotel-industry marketing post, Jun 2024), and the company ran its own webinars and an AMA. | Q5: 60 | R5: =IF(Q5>=60,"Priority",IF(Q5>=40,"Warm","Nurture")) | S5: US buyers don't know her yet. One askpolly insight post a week would work as both content and product demo. | T5: Hi Erin, congrats on the seed and the US push. Turning social conversations into valid research is a smart angle. Would be good to connect. | U5: Thanks for connecting, Erin. Honest question. askpolly surfaces the kind of insight that does really well on LinkedIn. Have you thought about posting some of it under your own name for the US market? | V5: a profile framed around Ottawa and Canada, no featured insight or demo, and a weekly "what people are actually saying about X" format. | W5: Canada. Polite and practical. If you email, CASL applies: it must be relevant to her role and include an unsubscribe. CASL applies to email | Y5: askpolly's US launch | Z5: Hi Erin, Congrats on the seed and the US go-to-market push. askpolly turns social conversations into insight. That kind of data does very well on LinkedIn, and right now none of it goes out under your name to the US buyers you want to reach. We build founder brands on LinkedIn, one insight post a week to start. Open to a 15-minute call to sketch it out? Prabal Gliped | LinkedIn personal branding for founders Not relevant? Reply "no" and I won't follow up. | AA5: Not found
A6: G005 | B6: 01 | C6: 2026-09-22 | D6: Radhika Patil | E6: Co-founder & CEO | F6: Cradlewise | G6: US | I6: https://www.linkedin.com/in/radhika-gandhi-patil | J6: Yes | K6: $12M Series A led by 3one4 Capital and Prudent, Sep 2026, for channel expansion, R&D and international markets. She's on the Forbes Technology Council. | L6: 2026-09 | N6: Milestone-only | O6: 2023-06 | P6: milestone-only, and silent recently. Indexed posts: product design award (2019), $7M raise (Nov 2021), US team growth (Apr 2022), #startupstories (Jun 2023). Nothing indexed since mid-2023. | Q6: 60 | R6: =IF(Q6>=60,"Priority",IF(Q6>=40,"Warm","Nurture")) | S6: a consumer hardware brand entering new markets. Her public voice builds retail partner and parent trust. | T6: Hi Radhika, congrats on the Series A. Cradlewise has been one of the more thoughtful hardware stories out of the India-US corridor. Would be good to connect. | U6: Thanks for connecting, Radhika. Quick one. With new channels and markets coming, do you want your own LinkedIn doing some of that trust-building? Or is it mostly a press and product-led push? | V6: activity gap since 2023, a featured section that doesn't reflect the Series A, and a content line on sleep science plus building hardware across two countries. | W6: US, based in SF, with an India connection. Be direct but warm. | Y6: Cradlewise, new markets | Z6: Hi Radhika, Congrats on the Series A and the international push. You've built great press around Cradlewise, but your own LinkedIn has been quiet since mid-2023. New retail partners and parents will look you up first. We run LinkedIn for founders: positioning, writing and a steady posting rhythm in your voice. Would a 15-minute call next week be useful? Prabal Gliped | LinkedIn personal branding for founders Not relevant? Reply "no" and I won't follow up. | AA6: Not found
A7: G006 | B7: 01 | C7: 2026-09-22 | D7: Shourya Agarwal | E7: Founder & CEO | F7: Flam | G7: US/India | I7: https://www.linkedin.com/in/shourya-agarwal-015947b5 | J7: Yes | K7: $40M Series B led by QED Investors, Sep 2026, with Olivier Pomel, Martin Chavez and Shah Rukh Khan among the backers. | L7: 2026-09 | N7: Company-news voice | O7: 2025-06 | P7: company-news voice. Regular posts through mid-2025 about customer wins (Aditya Birla Capital, Axis Max Life, Salesforce, Business Today), each one a logo announcement. Last indexed Jun 2025. | Q7: 60 | R7: =IF(Q7>=60,"Priority",IF(Q7>=40,"Warm","Nurture")) | S7: the buyers are CMOs, and they follow people. A point of view on "content people interact with" fits his product exactly. | T7: Hi Shourya, congrats on the Series B. The Salesforce and Axis Max Life rollouts on Flam were interesting to follow. Would be good to connect. | U7: Thanks for connecting, Shourya. Curious, with the US push, do you see your own LinkedIn as part of how CMOs discover Flam? Right now the posts are mostly launches, which undersells the thinking behind it. | V7: all posts are announcements, no view of his own on the future of brand content, and no US-facing framing. | W7: SF and Bengaluru. Use a US-direct tone and offer IST or PT slots. | X7: shourya@flamapp.com | Y7: Flam and US CMOs | Z7: Hi Shourya, Congrats on the $40M Series B. Flam sells interactive content to CMOs, yet your feed is mostly launch announcements. CMOs follow people with a point of view, and yours is the story behind Flam. We help founders build that voice on LinkedIn, from strategy to weekly posts. Open to 15 minutes to talk through a US-facing plan? Prabal Gliped | LinkedIn personal branding for founders Not relevant? Reply "no" and I won't follow up. | AA7: Verified | AB7: Prospeo BOUNCEBAN
A8: G007 | B8: 01 | C8: 2026-09-22 | D8: Jagnoor Singh | E8: CEO | F8: Practo | G8: India | I8: https://www.linkedin.com/in/jagnoors | J8: Yes | K8: named CEO effective 1 Sep 2026, after joining as COO in Jan 2025. Previously held senior roles at Airtel, Unacademy and OYO. Practo reports 40% growth and has been profitable for 2.5 years. | L8: 2026-09 | N8: Emerging writer | O8: 2026-07 | P8: emerging writer. Original leadership and health posts roughly every quarter: #growprofitably (Feb 2025, 56 comments), preventive health (Apr 2026), "Firm in meetings, approachable outside" (Jul 2026). | Q8: 50 | R8: =IF(Q8>=60,"Priority",IF(Q8>=40,"Warm","Nurture")) | S8: building a CEO voice distinct from the founder's. | T8: Hi Jagnoor, congrats on the CEO role. Saw your post on being firm in meetings and approachable outside. [one line on why it landed] Would be good to connect. | U8: Thanks for connecting, Jagnoor. The first months in a CEO seat are when people decide what you stand for. Is LinkedIn part of how you want to set that, or more of a side channel? | V8: a headline still in COO mode (check this), no CEO narrative yet, and a cadence of one post a quarter against a potential of one a week. | W8: same company as lead 19. Message Jagnoor first. Don't contact Shashank in the same week. If Jagnoor replies, the pitch can grow into a leadership pair (founder plus CEO). Contact before Shashank ND | X8: jagnoor.singh@practo.com | Y8: Your first 100 days | Z8: Hi Jagnoor, Congrats on stepping in as Practo's CEO. The first months in the seat are when the market decides what a CEO stands for. Your posts get real engagement (56 comments on #growprofitably), but they come about once a quarter. We help CXOs turn that into a steady, credible weekly presence with little time from them. Worth a 15-minute call to map your first 100 days on LinkedIn? Prabal Gliped | LinkedIn personal branding for founders Not relevant? Reply "no" and I won't follow up. | AA8: Verified | AB8: Prospeo BOUNCEBAN Prospeo profile linkedin.com/in/jagnoor-singh-65580910 (title still COO)
A9: G008 | B9: 01 | C9: 2026-09-22 | D9: Madhulima Tewari | E9: CEO | F9: VerifAIX | G9: India/US | I9: https://www.linkedin.com/in/maddietewari | J9: Yes | K9: $5M seed co-led by Endiya Partners and Bluehill VC, Sep 2026, for product, customer deployments and engineering hires. Co-founders are Kenneth Roe and Avner Landver. | L9: 2026-09 | N9: Milestone-only | O9: 2025-10 | P9: milestone-only. The one indexed post is about the RISC-V Summit (Oct 2025). | Q9: 50 | R9: =IF(Q9>=60,"Priority",IF(Q9>=40,"Warm","Nurture")) | S9: a technical thought-leadership voice to build trust with semiconductor buyers and senior engineers. | T9: Hi Madhulima, congrats on the seed. An AI trust layer for chip verification is a real gap. Saw VerifAIX at the RISC-V Summit. Would be good to connect. | U9: Thanks for connecting, Madhulima. In a field this specialised, a few people deciding to trust you matters more than reach. Is your LinkedIn part of how you reach verification leads, or mostly conferences? | V9: posts only at events, a profile that doesn't explain VerifAIX in one line, and a content line on verification bottlenecks. | W9: confirm where she's based before sending (India or US) and set the tone to match. Confirm location | Y9: VerifAIX, trust first | Z9: Hi Madhulima, Congrats on the $5M seed. In chip verification a handful of senior engineers decide who they trust. Right now VerifAIX shows up at events like the RISC-V Summit, but not much on LinkedIn between them. We build technical founder brands on LinkedIn, aimed at the few people who matter. Open to a quick call to see if it fits? Prabal Gliped | LinkedIn personal branding for founders Not relevant? Reply "no" and I won't follow up. | AA9: Not found
A10: G009 | B10: 01 | C10: 2026-09-22 | D10: Ben Armstrong | E10: CEO | F10: Cytix | G10: UK | I10: https://www.linkedin.com/in/benarmstrong2 | J10: Yes | K10: $7M (£5M) Series A led by Northern Gritstone, Aug 2026. He speaks at the Cyber Leaders' Summit. | L10: 2026-08 | N10: Went quiet | O10: 2024-09 | P10: went quiet. He used to post with personality in 2022 and 2023 ("We did it again!" with 29 comments, a post on why consultancies struggle with day rates, video content). Last indexed own post Sep 2024. The Series A was posted by Soapbox VC, not by him. | Q10: 50 | R10: =IF(Q10>=60,"Priority",IF(Q10>=40,"Warm","Nurture")) | S10: bring back what worked, a candid take on security testing, on a steady cadence. | T10: Hi Ben, congrats on the Series A. Came across your post on why consultancies struggle to drop the day rate. Still a live problem. Would be good to connect. | U10: Thanks for connecting, Ben. You used to post a fair bit, then it went quiet. Totally normal while building. Is getting back to it on the list now the round's done? | V10: a 2-year gap, the Series A story told by others, and a content line on AI-driven software change risk. | W10: UK, and North of England. Keep it low-key and skip the hype words. | Y10: Back to posting? | Z10: Hi Ben, Congrats on the Series A. You used to post regularly on LinkedIn, then it went quiet around 2024. The round was announced by others, not you. Enterprise security buyers respond to founders they recognise. We help founders get back to a steady rhythm without writing every post themselves. Worth 15 minutes next week to talk it through? Prabal Gliped | LinkedIn personal branding for founders Not relevant? Reply "no" and I won't follow up. | AA10: Not found
A11: G010 | B11: 01 | C11: 2026-09-22 | D11: Theo Saville | E11: Co-founder & CEO | F11: CloudNC | G11: UK | I11: https://www.linkedin.com/in/theosaville | J11: Yes | K11: €17.2M to scale AI-powered precision machining, Sep 2026. | L11: 2026-09 | N11: Went quiet | O11: 2024-02 | P11: went quiet after a strong run. 2023 was good: a "story of CloudNC" series, "Stealth mode: is it worth it?", CAM Assist at EMO, and a post from the CNC community on Reddit (Feb 2024). The company page now carries it (a drone tour of the factory, podcast clips). | Q11: 50 | R11: =IF(Q11>=60,"Priority",IF(Q11>=40,"Warm","Nurture")) | S11: restart the founder series. Machinists, manufacturers and investors all respond to him directly. | T11: Hi Theo, congrats on the new round. Went back through your "story of CloudNC" posts from 2023. [one line on the part that stuck] Would be good to connect. | U11: Thanks for connecting, Theo. Honest question. Those 2023 posts clearly worked, then the feed went to the company page. Was that a deliberate call or just time? | V11: a 2.5-year gap on his own feed, the company page doing work his voice did better, and a restart plan (the factory, machinists, the Reddit community). | W11: UK. Direct and specific. He'll spot generic copy immediately. Check for in-house marketing | X11: theo.saville@cloudnc.com | Y11: The CloudNC story, restarted | Z11: Hi Theo, Congrats on the new round. In 2023 you told the CloudNC story yourself on LinkedIn. Since early 2024 the storytelling has moved to the company page. Machinists and manufacturers follow you, not the logo. We help founders restart and keep that rhythm, with you in control of the voice. Open to a 15-minute call to see what a restart could look like? Prabal Gliped | LinkedIn personal branding for founders Not relevant? Reply "no" and I won't follow up. | AA11: Verified | AB11: Prospeo BOUNCEBAN
A12: G011 | B12: 01 | C12: 2026-09-22 | D12: Adrian Murray | E12: Founder & CEO | F12: Fisent Technologies | G12: Canada | I12: https://www.linkedin.com/in/adrianmurrray | J12: Yes | K12: $4.3M raise, Aug to Sep 2026. Toronto, GenAI process automation ("BizAI"). | L12: 2026-08 | N12: Milestone-only | O12: 2025-06 | P12: milestone-only. Company announcements from 2024 to 2025 ("growing fast", "successfully completes"), and others interviewing him (Pulse 2.0 in 2025, LaunchPad in May 2026). Last indexed own post Jun 2025. | Q12: 50 | R12: =IF(Q12>=60,"Priority",IF(Q12>=40,"Warm","Nurture")) | S12: turn the interview material into his own weekly posts for enterprise ops and finance buyers. | T12: Hi Adrian, congrats on the raise. The outcomes-as-a-service framing for GenAI automation is a sharp one. Would be good to connect. | U12: Thanks for connecting, Adrian. Other people keep telling Fisent's story in interviews. Your own feed doesn't yet. Is that something you'd want to change this year? | V12: interviews not reused as posts, a headline without the buyer outcome, and the gap since Jun 2025. | W12: Canada, Toronto. Polite and practical. | Y12: Fisent's story, your voice | Z12: Hi Adrian, Congrats on the raise. Other people keep telling Fisent's story in interviews, but your own LinkedIn has been quiet since mid-2025. Outcomes-as-a-service is a strong idea to own in public. We turn founders' thinking into a steady LinkedIn presence for enterprise buyers. Worth a 15-minute call to see how? Prabal Gliped | LinkedIn personal branding for founders Not relevant? Reply "no" and I won't follow up. | AA12: Not found
A13: G012 | B13: 01 | C13: 2026-09-22 | D13: Raghav Midha | E13: Co-founder & CEO | F13: Terminal | G13: Canada | I13: https://www.linkedin.com/in/raghavmidha | J13: Yes | K13: $20M Series A, Jul 2026. YC S23, a telematics data API for trucking. | L13: 2026-07 | N13: Company-news voice | O13: 2025-10 | P13: company-news voice. Indexed posts are hiring and job posts (Chief of Staff Jul 2024, jobs Mar 2025, engineers Oct 2025). | Q13: 50 | R13: =IF(Q13>=60,"Priority",IF(Q13>=40,"Warm","Nurture")) | S13: a founder brand as a recruiting engine, plus credibility with fleet and logistics buyers. | T13: Hi Raghav, congrats on the Series A. Telematics integration is unglamorous and really important. Following Terminal. Would be good to connect. | U13: Thanks for connecting, Raghav. I noticed your posts are mostly hiring. Makes sense. Have you tried writing about the problem itself? It tends to pull better engineers than job posts do. | V13: job posts only, no view of his own on trucking data, and a technical-founder content line for recruiting. | W13: Canada, Toronto, with a US and YC audience. Short and direct. | X13: raghav@withterminal.com | Y13: Hiring after the Series A | Z13: Hi Raghav, Congrats on the $20M Series A. Your LinkedIn is mostly job posts right now. Strong engineers pick founders whose thinking they've already seen. We help technical founders write about the problem they're solving, so hiring and fleet buyers come to them. Open to 15 minutes to talk it through? Prabal Gliped | LinkedIn personal branding for founders Not relevant? Reply "no" and I won't follow up. | AA13: Verified | AB13: Prospeo SMTP
A14: G013 | B14: 01 | C14: 2026-09-22 | D14: Doug Schweitzer | E14: CEO & co-founder | F14: Ultimarii | G14: Canada | I14: https://www.linkedin.com/in/doug-schweitzer-573a443b | J14: Yes | K14: Series A of more than $13M CAD led by BDC's Industrial Innovation Venture Fund, Sep 2026. Calgary, regulatory AI for infrastructure approvals. He's a former Alberta innovation minister and co-founded Blue Rock Law. | L14: 2026-09 | N14: Went quiet | O14: 2024-01 | P14: went quiet. From 2022 to 2024 he mostly shared news links about the Alberta economy (IBM Calgary with 42 comments, oil and gas labour with 39 comments). Last indexed Jan 2024. The Ultimarii page carries the company voice now. | Q14: 50 | R14: =IF(Q14>=60,"Priority",IF(Q14>=40,"Warm","Nurture")) | S14: move from minister and lawyer to AI infrastructure founder. The audience is energy and infrastructure executives and regulators. | T14: Hi Doug, congrats on the Ultimarii Series A. Speeding up infrastructure approvals is one of the more practical uses of AI I've seen. Would be good to connect. | U14: Thanks for connecting, Doug. People know you from your years in government. Fewer know you as a founder yet. Is shifting that part of the plan for this year? | V14: posts are shared articles rather than his own view, the positioning is still political and legal, and a founder narrative on approvals and energy projects. | W14: Canada, Alberta. Respectful. He likely has advisers, so expect a gatekeeper. Former Alberta minister | X14: doug.schweitzer@ultimarii.com | Y14: From minister to founder | Z14: Hi Doug, Congrats on Ultimarii's Series A. People know you from your years in government. Fewer know you yet as the founder speeding up infrastructure approvals with AI, and your LinkedIn still reads like the old role. We help founders reposition on LinkedIn with a steady voice aimed at energy and infrastructure leaders. Worth a 15-minute call? Prabal Gliped | LinkedIn personal branding for founders Not relevant? Reply "no" and I won't follow up. | AA14: Verified | AB14: Prospeo BOUNCEBAN
A15: G014 | B15: 01 | C15: 2026-09-22 | D15: Gabriel Rivest | E15: CEO & co-founder | F15: Scopia Surgical | G15: Canada | I15: https://www.linkedin.com/in/gabriel-rivest-11a019b4 | J15: Yes | K15: $2.65M CAD pre-seed co-led by Linearis Ventures and Anges Québec, Sep 2026. Montreal, AI surgical navigation. | L15: 2026-09 | N15: Milestone-only | O15: 2026-09-04 | P15: milestone-only, but active right now. A vision post (Feb 2025) and the funding post (4 Sep 2026). This is the only lead confirmed active in the last 30 days. | Q15: 50 | R15: =IF(Q15>=60,"Priority",IF(Q15>=40,"Warm","Nurture")) | S15: building credibility with clinicians and partners ahead of trials, with bilingual content. | T15: Hi Gabriel, congrats on closing the pre-seed. Real-time navigation for robotic surgery is a big bet. Following Scopia. Would be good to connect. | U15: Thanks for connecting, Gabriel. In medtech, surgeons and partners tend to check the founder before the product. Is building that voice something you're planning, in French, English or both? | V15: posts only at milestones, the profile language (FR vs EN), and a clinician-facing content line. | W15: Quebec. Offer French. Polite and practical. Active last 30 days; offer French | X15: gabriel@scopia.tech | Y15: Scopia's next chapter | Z15: Hi Gabriel, Congrats on closing the pre-seed. In medtech, surgeons and partners check the founder before the product. Right now you post at milestones only. We build founder brands on LinkedIn, in English, French or both, aimed at clinicians and partners. Open to a quick call to see what that could look like for Scopia? Prabal Gliped | LinkedIn personal branding for founders Not relevant? Reply "no" and I won't follow up. | AA15: Verified | AB15: Prospeo BOUNCEBAN
A16: G015 | B16: 01 | C16: 2026-09-22 | D16: David Lighton | E16: Founder & CEO | F16: Diameter Pay | G16: US | I16: https://www.linkedin.com/in/david-lighton-b027a917 | J16: Yes | K16: $10M Series A, Sep 2026. The company was bootstrapped before this round, and processed $300M in payment volume in 2023. | L16: 2026-09 | N16: Went quiet | O16: 2023-07 | P16: went quiet. In 2023 he shared finance and policy articles (de-risking China, Citadel buying into Western Alliance, legacy admissions). Nothing indexed since mid-2023. | Q16: 50 | R16: =IF(Q16>=60,"Priority",IF(Q16>=40,"Warm","Nurture")) | S16: the bootstrapped-to-Series A story, and a credible voice on stablecoin infrastructure. | T16: Hi David, congrats on the Series A. Bootstrapping to that point in payments is rare. Following Diameter. Would be good to connect. | U16: Thanks for connecting, David. You used to share sharp finance and policy reads. Then it went quiet. Is getting your own view out there part of the plan now that the round is done? | V16: link shares with no commentary, a 3-year gap, and a content line on stablecoin payments for banks. | W16: confirm his location (assumed US). Direct and numbers-first. Confirm location | Y16: Bootstrapped to Series A | Z16: Hi David, Congrats on the Series A. Bootstrapping to that point in payments is rare. That's a story banks and platforms want to hear, but your LinkedIn has been quiet since 2023. We help founders turn their thinking into a steady LinkedIn presence, aimed at the partners they need. Worth 15 minutes to talk it through? Prabal Gliped | LinkedIn personal branding for founders Not relevant? Reply "no" and I won't follow up. | AA16: Not found
A17: G016 | B17: 01 | C17: 2026-09-22 | D17: Leo Crowe | E17: Co-founder & CEO | F17: Souk | G17: UK | I17: https://www.linkedin.com/in/leo-crowe-457815121 | J17: Yes | K17: $1.6M pre-seed led by Sure Valley Ventures, with Antler and Fuel Ventures, Sep 2026. London, "Coco", an AI partner manager. | L17: 2026-09 | N17: Emerging writer | O17: 2026-04 | P17: emerging writer. Original takes about every 3 months: the Souk launch (Aug 2025), "one consistent problem across every..." (Jan 2026), "I told Souk our own ICP..." (Apr 2026). | Q17: 40 | R17: =IF(Q17>=60,"Priority",IF(Q17>=40,"Warm","Nurture")) | S17: from quarterly to weekly, without it eating his week. | T17: Hi Leo, congrats on the pre-seed. Saw your post on running Souk against its own ICP. [one line on the takeaway] Would be good to connect. | U17: Thanks for connecting, Leo. Your partnership posts are good, they just come every few months. Is weekly something you'd do if it only took 30 minutes of your time? | V17: cadence, no featured link to Coco, and one recurring format (the partner-activation playbook). | W17: UK. Pre-seed budget, so offer a lighter plan or pilot. Pre-seed budget | Y17: Weekly, not quarterly | Z17: Hi Leo, Congrats on the pre-seed. You already write about partnerships on LinkedIn, and your buyers live there. The gap is rhythm: a post every few months instead of every week. We help founders keep a weekly cadence in their own voice without it eating their week. Open to a quick call? Prabal Gliped | LinkedIn personal branding for founders Not relevant? Reply "no" and I won't follow up. | AA17: Not found
A18: G017 | B18: 01 | C18: 2026-09-22 | D18: Alex Harland | E18: Co-founder & CEO | F18: AI Score | G18: UK | I18: https://www.linkedin.com/in/alex-harland-a110b0149 | J18: Yes | K18: €4.6M raise, Sep 2026. London, keeping AI agents under control. He was on the founding team at the UK's NCSC; co-founder Benita Tibb is a former City lawyer. | L18: 2026-09 | N18: Emerging writer | O18: 2026-02 | P18: emerging writer. Technical opinion posts about every 6 months: OPA/Rego (Aug 2025), "AI governance does not belong in .pdf" (Feb 2026). | Q18: 40 | R18: =IF(Q18>=60,"Priority",IF(Q18>=40,"Warm","Nurture")) | S18: category-creation thought leadership. | T18: Hi Alex, congrats on the round. "AI governance does not belong in a PDF" is a line more people need to hear. Would be good to connect. | U18: Thanks for connecting, Alex. You've got a clear point of view on AI governance. It shows up about twice a year. Is building that into a regular voice on the list for AI Score? | V18: cadence, NCSC credibility not front and centre, and a split between technical and board-level posts. | W18: UK. Precise and low-hype. Expect security-minded scepticism. | Y18: AI governance, out loud | Z18: Hi Alex, Congrats on the round. You have a clear point of view on AI governance, and CISOs and GCs need to hear it more than twice a year. We help founders turn that point of view into a steady LinkedIn presence that builds the category with them in it. Worth a 15-minute call next week? Prabal Gliped | LinkedIn personal branding for founders Not relevant? Reply "no" and I won't follow up. | AA18: Not found
A19: G018 | B19: 01 | C19: 2026-09-22 | D19: Shishir Bankapur | E19: CEO | F19: Helogen | G19: US | I19: https://www.linkedin.com/in/shishir-work | J19: Yes | K19: $7.1M seed co-led by RRE Ventures and Oceans, Sep 2026. NYC, space biotech and in-orbit manufacturing. | L19: 2026-09 | N19: Emerging writer | O19: 2026-06 | P19: emerging writer. Big-idea posts now and then: the AgResearch partnership (Apr 2025) and "The next industrial revolution isn't on earth" (Jun 2026). | Q19: 40 | R19: =IF(Q19>=60,"Priority",IF(Q19>=40,"Warm","Nurture")) | S19: an explainer-led founder voice. | T19: Hi Shishir, congrats on the seed. "The next industrial revolution isn't on earth" is a good way to put it. Would be good to connect. | U19: Thanks for connecting, Shishir. Space biomanufacturing needs a lot of explaining, and you do it well. Are you planning to make that a regular thing, or keep it to big moments? | V19: cadence, no plain-English line on what Helogen makes, and an explainer series. | W19: US East. Direct. | X19: shishir@helogen.com | Y19: Explaining Helogen | Z19: Hi Shishir, Congrats on the seed. Space biomanufacturing needs a lot of explaining to investors, talent and early customers. "The next industrial revolution isn't on earth" is a good frame, and it deserves a regular slot. We help frontier founders build an explainer-led presence on LinkedIn. Open to a quick call to see how? Prabal Gliped | LinkedIn personal branding for founders Not relevant? Reply "no" and I won't follow up. | AA19: Verified | AB19: Prospeo SMTP Prospeo profile linkedin.com/in/shishir-b-40ba0a126 (Helogen CEO)
A20: G019 | B20: 01 | C20: 2026-09-22 | D20: Shashank ND | E20: Founder MD & Exec Chairman | F20: Practo | G20: India | I20: https://www.linkedin.com/in/shashanknd | J20: Yes | K20: moved from CEO to MD and Executive Chairman on 1 Sep 2026. He'll lead capital strategy, inorganic growth and innovation. | L20: 2026-09 | N20: Company-news voice | O20: 2026-01 | P20: company-news voice with a big-moment cadence: annual letters (FY24, Jun 2024), market launches (UAE May 2025, US Jan 2026). Media covers him often (the AI transformation piece and the Cent launch, Mar 2026). | Q20: 40 | R20: =IF(Q20>=60,"Priority",IF(Q20>=40,"Warm","Nurture")) | S20: the chairman narrative. Fewer operations posts, more on long-term bets. | T20: Hi Shashank, congratulations on the new role at Practo. The move into the US and UAE has been interesting to follow. Would be good to connect. | U20: Thanks for connecting, Shashank. Moving from CEO to chairman usually changes what people expect to hear from you. Is that something you're thinking about for LinkedIn? | W20: only after lead 7 has been contacted and at least a week has passed. The likely route is through his comms or CoS. India, senior. Very respectful and short. Wait 1 week after Jagnoor | X20: shashank@centai.in | Y20: The chairman's voice | Z20: Hi Shashank, Congratulations on the new role at Practo. Moving from CEO to Executive Chairman changes what people expect to hear from you: capital, AI and the long-term bets, not operations. We help senior leaders shape that narrative on LinkedIn, with a light touch on their time. Would a short call be useful, with you or whoever runs your comms? Prabal Gliped | LinkedIn personal branding for founders Not relevant? Reply "no" and I won't follow up. | AA20: Verified | AB20: Prospeo SMTP Address is at Cent (his preventive-health company) not Practo
A21: G020 | B21: 01 | C21: 2026-09-22 | D21: Ilan Zerbib | E21: Founder & CEO | F21: Sapiom | G21: US | I21: https://www.linkedin.com/in/izerbib | J21: Yes | K21: $15.75M seed with Accel (Feb 2026), then a $35M Series A (Aug 2026). SF, AI agents and agentic payments. He spent nearly 5 years at Shopify. | L21: 2026-08 | N21: Already consistent | O21: 2026-08 | P21: already consistent, the most active in the batch. Roughly monthly original posts in 2026: the Shopify chapter (Oct 2025), the seed (Feb), Okta Ventures (Feb), "Building with Sapiom" (Jul), "Eleven months ago I founded Sapiom" (Aug). | Q21: 40 | R21: =IF(Q21>=60,"Priority",IF(Q21>=40,"Warm","Nurture")) | S21: go from monthly to weekly and turn big posts into series, so a CEO of a fast-growing company gets the hours back. | T21: Hi Ilan, congrats on the Series A. Saw your "eleven months ago I founded Sapiom" post. [one line on what stood out] Would be good to connect. | U21: Thanks for connecting, Ilan. You're one of the few founders who actually posts consistently. Curious, how much of your week does it take right now? | V21: go from monthly to weekly, reuse the long posts, and his agentic payments point of view for the buyers. | W21: US West. Numbers-first. He'll judge Gliped on its own profile, so make sure it's current. Pitch time and reach not starting | X21: ilan@sapiom.ai | Y21: Your weekly hours back | Z21: Hi Ilan, Congrats on the Series A. You're one of the few founders who posts consistently. That usually costs hours a week that a CEO of a fast-growing company doesn't have. We keep founders' voice and rhythm while taking the writing and repurposing off their plate. Worth 15 minutes to see what you'd get back? Prabal Gliped | LinkedIn personal branding for founders Not relevant? Reply "no" and I won't follow up. | AA21: Verified | AB21: Prospeo SMTP
A22: G021 | B22: 02 | C22: 2026-09-25 | D22: Aniket Shah | E22: Co-founder & CEO | F22: Swish | G22: India | H22: Bengaluru | I22: https://www.linkedin.com/in/aniketshah30 | J22: Yes | K22: $24M led by Bertelsmann India, with Accel and Bain Capital Ventures, to expand its 10-minute kitchen network | L22: 2026-09-10 | M22: https://entrackr.com/news/10-minute-food-delivery-startup-swish-raises-24-mn-led-by-bertelsmann-india-investments-12513814 | N22: Milestone-only | O22: 2025-03 | P22: Indexed own posts: Founder's Office hiring (Jan 2025) and the last raise (Mar 2025). Co-founder Ujjwal Sukheja wrote the founding story the same week. Nothing indexed since. | Q22: 60 | R22: =IF(Q22>=60,"Priority",IF(Q22>=40,"Warm","Nurture")) | S22: Quick commerce is crowded. The founder who explains why 10-minute fresh food works wins hires and press between rounds. | T22: Hi Aniket, congrats on the new round. Neighbourhood kitchens within a kilometre is a sharp way to make 10 minutes work. Would be good to connect. | U22: Thanks for connecting, Aniket. Quick one. With the kitchen network growing, do you want your own LinkedIn telling that story? Or is it mostly the brand account for now? | V22: Posts only at raises and hiring; no view of his own on hyperlocal food ops; featured section not pointing to Swish. | W22: Co-founders Ujjwal Sukheja and Saran S. also post. Pitch Aniket first. | X22: aniket@justswish.in | Y22: Swish's founder story | Z22: Hi Aniket, Congrats on the $24M round. Quick commerce is crowded, and Swish's story mostly shows up at raises and hiring posts. The founder who explains why 10-minute fresh food works wins the best hires and the press in between. We build founder brands on LinkedIn, from positioning to weekly posts. Open to a 15-minute call next week? Prabal Gliped | LinkedIn personal branding for founders Not relevant? Reply "no" and I won't follow up. | AA22: Verified | AB22: Prospeo SMTP
A23: G022 | B23: 02 | C23: 2026-09-25 | D23: Sunil Gupta | E23: Co-founder & CEO | F23: QNu Labs | G23: India | H23: Bengaluru | I23: https://www.linkedin.com/in/sunil-gupta-1733754 | J23: Yes | K23: Rs 200 Cr Series A1 co-led by National Quantum Mission and Speciale Invest, with Sony Innovation Fund | L23: 2026-09-09 | M23: https://startuptalky.com/news/daily-indian-funding-roundup-key-news-9-september-2026/ | N23: Company-news voice | O23: 2025-12 | P23: Posts company milestones one to three times a year since 2021: IMC 2022 (28 comments), India's first quantum telecom link, Tracxn ranking, a Dec 2025 breakthrough post. All announcements. | Q23: 50 | R23: =IF(Q23>=60,"Priority",IF(Q23>=40,"Warm","Nurture")) | S23: Quantum security needs explaining to CISOs and government buyers. A founder voice on why quantum-safe matters now turns announcements into trust. | T23: Hi Sunil, congrats on the Series A1. Quantum-safe security built out of India is a story more CISOs should hear. Would be good to connect. | U23: Thanks for connecting, Sunil. Your posts mostly announce QNu milestones. Have you thought about explaining the why behind quantum-safe for buyers who are still catching up? | V23: Announcement-only feed; no plain-language line on what QNu does; no cadence between milestones. | W23: Deep tech, government and defence buyers. Keep it formal. | X23: sunil@qnulabs.com | Y23: Quantum-safe, explained | Z23: Hi Sunil, Congrats on the Rs 200 Cr Series A1. Your LinkedIn announces QNu's milestones well. What most CISOs and government buyers still need is the why: why quantum-safe, why now. We help deep-tech founders build that voice on LinkedIn, steadily and credibly. Worth a 15-minute call to see how it could work for you? Prabal Gliped | LinkedIn personal branding for founders Not relevant? Reply "no" and I won't follow up. | AA23: Verified | AB23: Prospeo SMTP
A24: G023 | B24: 02 | C24: 2026-09-25 | D24: Prashant Shah | E24: Co-founder & CEO | F24: Definedge | G24: India | H24: Pune | I24: https://www.linkedin.com/in/prashant-shah-definedge | J24: Yes | K24: Rs 22 Cr pre-Series A; total raised Rs 30 Cr; 14+ trading and investing platforms (Opstra, Zone, Algostra) | L24: 2026-09-22 | M24: https://entrackr.com/snippets/fintech-and-brokerage-startup-definedge-raises-rs-22-cr-in-pre-series-a-12562400 | N24: Milestone-only | O24: 2025-12 | P24: One own post indexed (Dec 2025, a Definedge milestone). Holds CMT, CFTe, MFTA and MSTA, so he has deep technical-analysis credibility that barely shows on LinkedIn. | Q24: 50 | R24: =IF(Q24>=60,"Priority",IF(Q24>=40,"Warm","Nurture")) | S24: Retail traders follow people, not platforms. His chartered-technician credibility is the brand asset. | T24: Hi Prashant, congrats on the pre-Series A. Fourteen platforms for retail traders out of Pune is a lot of product. Would be good to connect. | U24: Thanks for connecting, Prashant. You carry more technical-analysis credentials than most people posting about markets. Is building a voice on LinkedIn part of the plan now? | V24: Credentials in headline but no educational posts; no link to Definedge platforms; posts only at milestones. | W24: Check whether he already posts on YouTube or X. If so, pitch repurposing onto LinkedIn. | X24: prashant.shah@definedge.com | Y24: Your credentials, visible | Z24: Hi Prashant, Congrats on the pre-Series A. You carry more technical-analysis credentials than most people posting about markets, yet they barely show on LinkedIn. Retail traders follow people, not platforms. We turn founders' expertise into a steady LinkedIn presence that pulls users to the product. Open to a quick call? Prabal Gliped | LinkedIn personal branding for founders Not relevant? Reply "no" and I won't follow up. | AA24: Verified | AB24: Prospeo SMTP Prospeo headline: Co-founder & CEO
A25: G024 | B25: 02 | C25: 2026-09-25 | D25: Abhijit (AB) Gupta | E25: Co-founder | F25: Popo Global (The Pizza Bakery, Paris Panini, Smash Guys) | G25: India | H25: Bengaluru | I25: https://www.linkedin.com/in/ab-gupta-9b1b8210 | J25: Yes | K25: Rs 532 Cr from Artal Asia to expand beyond Bengaluru | L25: 2026-09-11 | M25: https://entrackr.com/snippets/the-pizza-bakery-operator-popo-global-raises-rs-532-cr-from-artal-asia-12518089 | N25: Went quiet | O25: 2023-04 | P25: Posted 'Growth Stories: Lessons from The Pizza Bakery' (Apr 2023) and spoke on an investor panel about building F&B without growth capital (May 2023). The company page carries it since. | Q25: 60 | R25: =IF(Q25>=60,"Priority",IF(Q25>=40,"Warm","Nurture")) | S25: He built without outside capital and now has Rs 532 Cr. That's a founder story F&B operators and new-city hires will follow. | T25: Hi AB, congrats on the Artal round. Building The Pizza Bakery without growth capital first makes this one more interesting. Would be good to connect. | U25: Thanks for connecting, AB. Your growth-stories episode from 2023 was one of the few times you told the story yourself. With new cities coming, is that something you want to do more of? | V25: Three-year gap; profile doesn't show the three brands; expansion story is untold. | W25: Co-founder brother Nikhil Gupta. Pitch AB first. | Y25: Pizza Bakery, next cities | Z25: Hi AB, Congrats on the Rs 532 Cr round from Artal. You built The Pizza Bakery without growth capital. That's a founder story F&B operators, landlords and new-city hires will follow, and it hasn't been on your LinkedIn since 2023. We build founder brands on LinkedIn around stories like that. Worth 15 minutes to talk it through? Prabal Gliped | LinkedIn personal branding for founders Not relevant? Reply "no" and I won't follow up. | AA25: Not found
A26: G025 | B26: 02 | C26: 2026-09-25 | D26: Karan Jain | E26: Founder & CEO | F26: Carrum Mobility | G26: India | H26: Bengaluru | I26: https://www.linkedin.com/search/results/people/?keywords=Karan%20Jain%20Carrum%20Mobility | J26: No | K26: $10M Series B led by Uber at about $168M valuation; business nearly doubled since January; profitable since month one | L26: 2026-09-09 | M26: https://techcrunch.com/2026/09/09/uber-invests-10m-in-indian-fleet-operator-carrum-at-168m-valuation/ | N26: Not indexed | P26: No own posts indexed. Several people share the name, so confirm the profile first. He previously founded Revv (acquired by CarDekho). | Q26: 60 | R26: =IF(Q26>=60,"Priority",IF(Q26>=40,"Warm","Nurture")) | S26: Second-time founder, profitable from month one, backed twice by Uber. A rare story in mobility that he isn't telling. | T26: Hi Karan, congrats on the Uber round. Profitable from month one in fleet management is rare. Following Carrum. Would be good to connect. | U26: Thanks for connecting, Karan. Between Revv and Carrum you've got a founder story most people in mobility would want to hear. Is LinkedIn somewhere you want to tell it? | V26: Confirm profile; check headline mentions Revv exit; content line on profitable fleet ops and the EV and CNG shift. | W26: Confirm profile before sending. | Y26: Profitable from month one | Z26: Hi Karan, Congrats on the Uber-led round. A second-time founder, profitable from month one, backed twice by Uber. Very few people in mobility can tell that story, and right now you're not telling it on LinkedIn. We build founder brands on LinkedIn, from positioning to weekly posts. Open to a 15-minute call next week? Prabal Gliped | LinkedIn personal branding for founders Not relevant? Reply "no" and I won't follow up. | AA26: Not found
A27: G026 | B27: 02 | C27: 2026-09-25 | D27: Abhishek Murarka | E27: Co-founder & CEO | F27: Circolife | G27: India | I27: https://www.linkedin.com/in/abhishek-murarka-633b876 | J27: Yes | K27: $4.5M (Rs 40.45 Cr) pre-Series A anchored by Bharat Jaisinghani of Polycab, with Nitish Mittersain; target 40,000 cooling units | L27: 2026-09-08 | M27: https://www.exchange4media.com/industry-briefing-news/circolife-raises-45-mn-pre-series-a-158085.html | N27: Not indexed | P27: Indexed posts under this name are about investing and wealth (2021 to 2024) and may be a different person. The Circolife company page posts regularly. | Q27: 50 | R27: =IF(Q27>=60,"Priority",IF(Q27>=40,"Warm","Nurture")) | S27: Cooling-as-a-service is a new category. Businesses buying it want to trust the operator behind it. | T27: Hi Abhishek, congrats on the pre-Series A. Cooling as a subscription is a smart model for Indian offices. Would be good to connect. | U27: Thanks for connecting, Abhishek. The company page is doing the talking for Circolife right now. Is building your own voice around the category something you've thought about? | V27: Confirm profile; company page posts, founder silent; content line on energy savings and IoT maintenance. | W27: Profile confirmed via Prospeo (CEO & Co-Founder, Circolife). Indexed posts under this name were a different person. | X27: abhishek@circolife.com | Y27: Cooling as a category | Z27: Hi Abhishek, Congrats on the pre-Series A. Cooling-as-a-service is a new category, and businesses buying it want to trust the operator behind it. Right now Circolife's page does the talking. We help founders build their own voice on LinkedIn around the category they're creating. Worth a quick call to see if it fits? Prabal Gliped | LinkedIn personal branding for founders Not relevant? Reply "no" and I won't follow up. | AA27: Verified | AB27: Prospeo SMTP PROFILE https://www.linkedin.com/in/abhishek-murarka-633b876 (CEO & Co-Founder Circolife)
A28: G027 | B28: 02 | C28: 2026-09-25 | D28: Sneha Priya Reddy | E28: Co-founder | F28: UniqYou | G28: India | H28: Bengaluru | I28: https://www.linkedin.com/search/results/people/?keywords=Sneha%20Priya%20Reddy%20UniqYou | J28: No | K28: Rs 15.8 Cr seed led by Arkam Ventures and Antler; company founded 2026; angels include Myntra's co-founder and former CEO | L28: 2026-09-14 | M28: https://startuptalky.com/news/daily-indian-funding-roundup-key-news-14-september-2026/ | N28: Not indexed | P28: No own posts indexed. Brand-new company, so her founder presence is starting from zero. | Q28: 60 | R28: =IF(Q28>=60,"Priority",IF(Q28>=40,"Warm","Nurture")) | S28: Women's fashion is built on trust and taste. A founder-led feed at launch is cheaper than paid acquisition. | T28: Hi Sneha, congrats on the seed. A tech-first platform for women's fashion with the Myntra founders behind it is a strong start. Would be good to connect. | U28: Thanks for connecting, Sneha. In fashion, people buy into the founder's taste first. Is your own LinkedIn part of the launch plan for UniqYou? | V28: Confirm profile; launch story; build-in-public format for the first 90 days. | W28: Confirm profile. Co-founder Nishanth Jois. | Y28: UniqYou's launch voice | Z28: Hi Sneha, Congrats on the seed, and on backers like the Myntra founders. In fashion, people buy into the founder's taste first. A founder-led LinkedIn at launch often costs less than paid acquisition and brings hires with it. We build founder brands on LinkedIn from day one. Open to 15 minutes to plan your first 90 days? Prabal Gliped | LinkedIn personal branding for founders Not relevant? Reply "no" and I won't follow up. | AA28: Not found
A29: G028 | B29: 02 | C29: 2026-09-25 | D29: Ankit Joshi | E29: Co-founder | F29: TRUE ARTIS | G29: India | H29: Delhi NCR | I29: https://www.linkedin.com/search/results/people/?keywords=Ankit%20Joshi%20TRUE%20ARTIS | J29: No | K29: Rs 11.4 Cr seed led by Zeropearl VC, with Medanta co-founder's group Eleven; two aesthetic surgery centres in Delhi and Gurgaon | L29: 2026-09-16 | M29: https://startuptalky.com/news/daily-indian-funding-roundup-key-news-16-september-2026/ | N29: Not indexed | P29: No own posts indexed that clearly match. Many profiles share the name. | Q29: 50 | R29: =IF(Q29>=60,"Priority",IF(Q29>=40,"Warm","Nurture")) | S29: Aesthetic surgery is a trust purchase. A founder who explains safety and standards sets the brand apart from clinics. | T29: Hi Ankit, congrats on the seed. An integrated aesthetic surgery platform with Medanta-linked backing is a strong signal. Would be good to connect. | U29: Thanks for connecting, Ankit. In aesthetics, patients check who's behind the clinic before they book. Is founder content part of how you want to build TRUE ARTIS? | V29: Confirm profile; trust and safety content line; doctor partner features. | W29: Confirm profile. Co-founder Sandeep Upadhyay. Medical advertising rules apply to content. | Y29: TRUE ARTIS, trust first | Z29: Hi Ankit, Congrats on the seed. In aesthetic surgery, patients check who's behind the clinic before they book. A founder who talks openly about safety and standards sets TRUE ARTIS apart. We build founder brands on LinkedIn, carefully and within medical advertising norms. Worth a 15-minute call? Prabal Gliped | LinkedIn personal branding for founders Not relevant? Reply "no" and I won't follow up. | AA29: Not found
A30: G029 | B30: 02 | C30: 2026-09-25 | D30: Devang Kumar | E30: Founder & CEO | F30: Greenwave Circularity | G30: India | H30: Odisha | I30: https://www.linkedin.com/search/results/people/?keywords=Devang%20Kumar%20Greenwave%20Circularity | J30: No | K30: $31.5M financing from OeEB (Development Bank of Austria) for a closed-loop PET recycling plant; JV with a Coca-Cola bottler | L30: 2026-09-09 | M30: https://indianstartupnews.com/funding/greenwave-circularity-raises-315-million-from-oeeb-for-odisha-pet-recycling-plant-12516293 | N30: Not indexed | P30: No own posts indexed. | Q30: 50 | R30: =IF(Q30>=60,"Priority",IF(Q30>=40,"Warm","Nurture")) | S30: Circular economy buyers (brands, bottlers, ESG teams) look for credible operators. A founder voice on recycled PET fills that gap. | T30: Hi Devang, congrats on the OeEB financing. Closed-loop PET recycling at that scale is what brand ESG targets need. Would be good to connect. | U30: Thanks for connecting, Devang. Most brand sustainability leads are on LinkedIn. Is building a voice there part of how you plan to win offtake partners? | V30: Confirm profile; ESG buyer content line; plant progress series. | W30: Confirm profile. This is debt financing, not equity, so avoid calling it a round. | Y30: Greenwave and ESG buyers | Z30: Hi Devang, Congrats on the OeEB financing. The brand sustainability leads you'll want as offtake partners are on LinkedIn. A founder voice on closed-loop PET recycling gives them a reason to call you first. We build founder brands on LinkedIn, aimed at the buyers that matter. Open to a quick call? Prabal Gliped | LinkedIn personal branding for founders Not relevant? Reply "no" and I won't follow up. | AA30: Not found
A31: G030 | B31: 02 | C31: 2026-09-25 | D31: Avni Jain | E31: Founder | F31: Nuvah | G31: India | I31: https://www.linkedin.com/in/avni-jain-05b45448 | J31: Yes | K31: Rs 4 Cr pre-seed from Amit Jain (CarDekho), Shantanu Deshpande (Bombay Shaving Co) and Ishendra Agarwal (GIVA); comfort-engineered heels | L31: 2026-09-22 | M31: https://startuptalky.com/news/nuvah-raises-4-crore-pre-seed-comfort-heels/ | N31: Not indexed | P31: No own posts indexed that match. Ex-McKinsey, Goldman Sachs and VC; IIM Ahmedabad. | Q31: 50 | R31: =IF(Q31>=60,"Priority",IF(Q31>=40,"Warm","Nurture")) | S31: D2C founder with a product-obsession story (24 prototypes, 900 hours of wear testing). That's content. | T31: Hi Avni, congrats on the pre-seed. 24 prototypes to get a heel that doesn't hurt is the kind of detail that sells. Would be good to connect. | U31: Thanks for connecting, Avni. The build story behind Nuvah is strong content on its own. Is founder-led content part of the launch plan? | V31: Confirm profile; build-in-public series; headline from consulting to founder. | W31: Profile confirmed via Prospeo (Founder & CEO, Nuvah). Pre-seed budget. | X31: avni@nuvah.in | Y31: 24 prototypes is content | Z31: Hi Avni, Congrats on the pre-seed. 24 prototypes and 900 hours of wear testing to get a heel that doesn't hurt. That build story is content most D2C founders would kill for. We help founders turn stories like that into a steady LinkedIn presence, sized for an early-stage budget. Worth a 15-minute call? Prabal Gliped | LinkedIn personal branding for founders Not relevant? Reply "no" and I won't follow up. | AA31: Verified | AB31: Prospeo SMTP PROFILE https://www.linkedin.com/in/avni-jain-05b45448 (Founder & CEO Nuvah)
A32: G031 | B32: 02 | C32: 2026-09-25 | D32: Charlie Bullock | E32: Co-founder & CEO | F32: Scan.com | G32: UK | H32: London | I32: https://www.linkedin.com/in/charlie-bullock | J32: Yes | K32: $220M incl. $90M Series C equity led by Noteus Partners, to build the largest US imaging network | L32: 2026-08-31 | M32: https://www.businesswire.com/news/home/20260831019981/en/Scan.com-Raises-$220-Million-to-Build-the-Largest-Medical-Imaging-Network-in-the-US | N32: Milestone-only | O32: 2025-03 | P32: Forbes 30 Under 30 (Apr 2024), Deloitte recognition (Nov 2024), a healthtech diagnostics post with 59 comments (Mar 2025). Last own post indexed Mar 2025. | Q32: 60 | R32: =IF(Q32>=60,"Priority",IF(Q32>=40,"Warm","Nurture")) | S32: Moving the centre of gravity to the US. US health systems and partners don't know him yet. | T32: Hi Charlie, congrats on the Series C. Building a national imaging network in the US from a UK start is a big move. Would be good to connect. | U32: Thanks for connecting, Charlie. Your posts do well when you post. The last one I could find was March 2025. With the US push, is getting back to it on the list? | V32: 18-month gap; UK framing; US health-system audience content line. | W32: Likely has comms support. Ask who owns his LinkedIn. | X32: charlie@scan.com | Y32: Scan.com's US chapter | Z32: Hi Charlie, Congrats on the Series C and the US push. Your posts land well when you post, but the last one I could find was March 2025. US health systems and partners are meeting you for the first time now. We help founders keep a steady, credible LinkedIn presence, working with your comms team. Worth a 15-minute call? Prabal Gliped | LinkedIn personal branding for founders Not relevant? Reply "no" and I won't follow up. | AA32: Verified | AB32: Prospeo SMTP Based in Atlanta per Prospeo
